Traceback (most recent call last):
  File "/Users/tompkins/Library/Python/3.9/lib/python/site-packages/jupyter_cache/executors/utils.py", line 51, in single_nb_execution
    executenb(
  File "/Users/tompkins/Library/Python/3.9/lib/python/site-packages/nbclient/client.py", line 1112, in execute
    return NotebookClient(nb=nb, resources=resources, km=km, **kwargs).execute()
  File "/Users/tompkins/Library/Python/3.9/lib/python/site-packages/nbclient/util.py", line 74, in wrapped
    return just_run(coro(*args, **kwargs))
  File "/Users/tompkins/Library/Python/3.9/lib/python/site-packages/nbclient/util.py", line 53, in just_run
    return loop.run_until_complete(coro)
  File "/usr/local/Cellar/python@3.9/3.9.2_1/Frameworks/Python.framework/Versions/3.9/lib/python3.9/asyncio/base_events.py", line 642, in run_until_complete
    return future.result()
  File "/Users/tompkins/Library/Python/3.9/lib/python/site-packages/nbclient/client.py", line 553, in async_execute
    await self.async_execute_cell(
  File "/Users/tompkins/Library/Python/3.9/lib/python/site-packages/nbclient/client.py", line 857, in async_execute_cell
    self._check_raise_for_error(cell, exec_reply)
  File "/Users/tompkins/Library/Python/3.9/lib/python/site-packages/nbclient/client.py", line 760, in _check_raise_for_error
    raise CellExecutionError.from_cell_and_msg(cell, exec_reply_content)
nbclient.exceptions.CellExecutionError: An error occurred while executing the following cell:
------------------
import matplotlib.pyplot as plt
import numpy as np


def tau(T):
    """optical depth as function of temperature"""
    return 0.56+0.07*np.exp(-Lv*(1/T-1/288)/Rv)

def emiss(tau):
    """effective emissivity as function of optical depth"""
    return 0.5+exp(-tau)/2.


def cdTdt(S,T):
    """define the energy balance equation in a function"""
    return S*(1-alpha(T))/4 - eps_e*sigma*np.power(T,4)

# vector of surface temperatures
Ts=np.arange(200,400,5)

# vector of albedos
fig,ax=plt.subplots()

ax.plot(Ts,tau(Ts))
ax.set_xlabel("Ts (K)")
ax.set_ylabel("Tau")


------------------

[0;31m---------------------------------------------------------------------------[0m
[0;31mNameError[0m                                 Traceback (most recent call last)
[0;32m<ipython-input-1-3c87f5616d96>[0m in [0;36m<module>[0;34m[0m
[1;32m     22[0m [0mfig[0m[0;34m,[0m[0max[0m[0;34m=[0m[0mplt[0m[0;34m.[0m[0msubplots[0m[0;34m([0m[0;34m)[0m[0;34m[0m[0;34m[0m[0m
[1;32m     23[0m [0;34m[0m[0m
[0;32m---> 24[0;31m [0max[0m[0;34m.[0m[0mplot[0m[0;34m([0m[0mTs[0m[0;34m,[0m[0mtau[0m[0;34m([0m[0mTs[0m[0;34m)[0m[0;34m)[0m[0;34m[0m[0;34m[0m[0m
[0m[1;32m     25[0m [0max[0m[0;34m.[0m[0mset_xlabel[0m[0;34m([0m[0;34m"Ts (K)"[0m[0;34m)[0m[0;34m[0m[0;34m[0m[0m
[1;32m     26[0m [0max[0m[0;34m.[0m[0mset_ylabel[0m[0;34m([0m[0;34m"Tau"[0m[0;34m)[0m[0;34m[0m[0;34m[0m[0m

[0;32m<ipython-input-1-3c87f5616d96>[0m in [0;36mtau[0;34m(T)[0m
[1;32m      5[0m [0;32mdef[0m [0mtau[0m[0;34m([0m[0mT[0m[0;34m)[0m[0;34m:[0m[0;34m[0m[0;34m[0m[0m
[1;32m      6[0m     [0;34m"""optical depth as function of temperature"""[0m[0;34m[0m[0;34m[0m[0m
[0;32m----> 7[0;31m     [0;32mreturn[0m [0;36m0.56[0m[0;34m+[0m[0;36m0.07[0m[0;34m*[0m[0mnp[0m[0;34m.[0m[0mexp[0m[0;34m([0m[0;34m-[0m[0mLv[0m[0;34m*[0m[0;34m([0m[0;36m1[0m[0;34m/[0m[0mT[0m[0;34m-[0m[0;36m1[0m[0;34m/[0m[0;36m288[0m[0;34m)[0m[0;34m/[0m[0mRv[0m[0;34m)[0m[0;34m[0m[0;34m[0m[0m
[0m[1;32m      8[0m [0;34m[0m[0m
[1;32m      9[0m [0;32mdef[0m [0memiss[0m[0;34m([0m[0mtau[0m[0;34m)[0m[0;34m:[0m[0;34m[0m[0;34m[0m[0m

[0;31mNameError[0m: name 'Lv' is not defined
NameError: name 'Lv' is not defined

